
Showing logs for build [32mcramte-jx-qs-python-master-n7jkm-3[0m stage [32mfrom-build-pack[0m and container [32mstep-credential-initializer-kbwmx[0m
{"level":"warn","ts":1580931766.0437586,"logger":"fallback-logger","caller":"logging/config.go:69","msg":"Fetch GitHub commit ID from kodata failed: \"ref: refs/heads/0.8.0-**-support-backwards-incompats\" is not a valid GitHub commit ID"}
{"level":"info","ts":1580931766.04484,"logger":"fallback-logger","caller":"creds-init/main.go:40","msg":"Credentials initialized."}

Showing logs for build [32mcramte-jx-qs-python-master-n7jkm-3[0m stage [32mfrom-build-pack[0m and container [32mstep-working-dir-initializer-h2mxb[0m
{"level":"warn","ts":1580931766.4343534,"logger":"fallback-logger","caller":"logging/config.go:69","msg":"Fetch GitHub commit ID from kodata failed: open /var/run/ko/HEAD: no such file or directory"}
{"level":"info","ts":1580931766.4361296,"logger":"fallback-logger","caller":"bash/main.go:64","msg":"Successfully executed command \"sh -c mkdir -p /workspace/source\"; output "}

Showing logs for build [32mcramte-jx-qs-python-master-n7jkm-3[0m stage [32mfrom-build-pack[0m and container [32mstep-place-tools[0m

Showing logs for build [32mcramte-jx-qs-python-master-n7jkm-3[0m stage [32mfrom-build-pack[0m and container [32mstep-git-source-cramte-jx-qs-python-master-n7jkm-wgs4j[0m
{"level":"warn","ts":1580931773.6066175,"logger":"fallback-logger","caller":"logging/config.go:69","msg":"Fetch GitHub commit ID from kodata failed: \"ref: refs/heads/0.8.0-**-support-backwards-incompats\" is not a valid GitHub commit ID"}
{"level":"info","ts":1580931777.8100283,"logger":"fallback-logger","caller":"git/git.go:103","msg":"Successfully cloned https://github.com/******/**-qs-python.git @ v0.0.3 in path /workspace/source"}

Showing logs for build [32mcramte-jx-qs-python-master-n7jkm-3[0m stage [32mfrom-build-pack[0m and container [32mstep-git-merge[0m
Using SHAs from PULL_REFS=master:b29959df06e74780d61765c16e32761af9c764f4
WARNING: no SHAs to merge, falling back to initial cloned commit

Showing logs for build [32mcramte-jx-qs-python-master-n7jkm-3[0m stage [32mfrom-build-pack[0m and container [32mstep-setup-jx-git-credentials[0m
Generated Git credentials file /workspace/xdg_config/git/credentials

Showing logs for build [32mcramte-jx-qs-python-master-n7jkm-3[0m stage [32mfrom-build-pack[0m and container [32mstep-build-python-unittest[0m

----------------------------------------------------------------------
Ran 0 tests in 0.000s

OK

Showing logs for build [32mcramte-jx-qs-python-master-n7jkm-3[0m stage [32mfrom-build-pack[0m and container [32mstep-build-container-build[0m
[36mINFO[0m[0000] Downloading base image python:onbuild        
[36mINFO[0m[0005] Error while retrieving image from cache: getting file info: stat /workspace/sha256:43780a8431c53f4afd734ad795e03127c0c607337a60639c5903a51a03535c22: no such file or directory 
[36mINFO[0m[0005] Downloading base image python:onbuild        
[36mINFO[0m[0009] Executing 3 build triggers                   
[36mINFO[0m[0009] Using files from context: [/workspace/source/requirements.txt] 
[36mINFO[0m[0009] Checking for cached layer docker.io/todo/cache:f96ea06eb1dc1e896fb6ba60e374488f43e9918d4fe1cb30c5f26c8dea340a73... 
[36mINFO[0m[0012] No cached layer found for cmd RUN pip install --no-cache-dir -r requirements.txt 
[36mINFO[0m[0012] Unpacking rootfs as cmd RUN pip install --no-cache-dir -r requirements.txt requires it. 
[36mINFO[0m[0034] Taking snapshot of full filesystem...        
[36mINFO[0m[0045] Using files from context: [/workspace/source/requirements.txt] 
[36mINFO[0m[0045] COPY requirements.txt /usr/src/app/          
[36mINFO[0m[0045] Taking snapshot of files...                  
[36mINFO[0m[0045] RUN pip install --no-cache-dir -r requirements.txt 
[36mINFO[0m[0045] cmd: /bin/sh                                 
[36mINFO[0m[0045] args: [-c pip install --no-cache-dir -r requirements.txt] 
You are using pip version 10.0.1, however version 20.0.2 is available.
You should consider upgrading via the 'pip install --upgrade pip' command.
[36mINFO[0m[0047] Taking snapshot of full filesystem...        
[36mINFO[0m[0051] Pushing layer docker.io/todo/cache:f96ea06eb1dc1e896fb6ba60e374488f43e9918d4fe1cb30c5f26c8dea340a73 to cache now 
[36mINFO[0m[0051] Using files from context: [/workspace/source] 
[36mINFO[0m[0051] COPY . /usr/src/app                          
[36mINFO[0m[0051] Taking snapshot of files...                  
[36mINFO[0m[0051] Using files from context: [/workspace/source/requirements.txt] 
[36mINFO[0m[0051] COPY requirements.txt .                      
[36mINFO[0m[0051] Taking snapshot of files...                  
[36mINFO[0m[0051] ENV PORT 8080                                
[36mINFO[0m[0051] No files changed in this command, skipping snapshotting. 
[36mINFO[0m[0051] EXPOSE 8080                                  
[36mINFO[0m[0051] cmd: EXPOSE                                  
[36mINFO[0m[0051] Adding exposed port: 8080/tcp                
[36mINFO[0m[0051] No files changed in this command, skipping snapshotting. 
[36mINFO[0m[0051] ENTRYPOINT ["python"]                        
[36mINFO[0m[0051] No files changed in this command, skipping snapshotting. 
[36mINFO[0m[0051] CMD ["app.py"]                               
[36mINFO[0m[0051] No files changed in this command, skipping snapshotting. 
[33mWARN[0m[0060] error uploading layer to cache: failed to push to destination index.docker.io/todo/cache:f96ea06eb1dc1e896fb6ba60e374488f43e9918d4fe1cb30c5f26c8dea340a73: unsupported status code 401; body:  
2020/02/05 19:44:05 mounted blob: sha256:06854774e2f35e4763103a446112c67322913a6177bea69eb49663e0166e6d6d
2020/02/05 19:44:05 mounted blob: sha256:1c7fe136a31e13a1c879245672184ced3b9fc590989ba42a522a57b071a9c1aa
2020/02/05 19:44:05 mounted blob: sha256:f0db43b9b8da254cebc77bf871006df01219e195b9853616b9f708f124a00f3a
2020/02/05 19:44:05 mounted blob: sha256:2d21c767035c4593de8bf7ad9781aa83ba110871d1a50871192f4e3480e6f11d
2020/02/05 19:44:05 mounted blob: sha256:e96bc319bce0351d1157092352bc5f85f8800c745388e60e86d06dec99285b45
2020/02/05 19:44:05 mounted blob: sha256:ece825d3308bbf98f708d95475ccd880497a1e2979ff4ef2534d49049a18488f
2020/02/05 19:44:05 mounted blob: sha256:e10b68fb77e6e91453cd4c1b02e2d77aa23a857cd8eb250617129d074478e1a5
2020/02/05 19:44:05 mounted blob: sha256:e2c0fb34dff3a1d32346b92e53fb88a14d1987b402a2348cb379c039687fabe2
2020/02/05 19:44:05 mounted blob: sha256:490280dbcfb772eb5731f059e38fcfacaeb75b4d005af7c249fd51926db2bd62
2020/02/05 19:44:06 pushed blob: sha256:f0082e35f25220cfac9c813f652e7e66b30effd3b98bf2f7e3cf72195ea5a2a7
2020/02/05 19:44:06 pushed blob: sha256:0232980cf8ed943426eb12d88f6fd4b6ae422548adb4ba760bdb7ffa343ca3e6
2020/02/05 19:44:06 pushed blob: sha256:85be923e614459afb03c57ddd06a1760f15de00b0816bf13f197c39f99066c6c
2020/02/05 19:44:07 pushed blob: sha256:740cde7de2bf36f7930002c69d7549581e766507e6f049e527e21870f00b22ef
2020/02/05 19:44:08 pushed blob: sha256:6ba7b6d01ece119e930bb19c043f8479d977975ed7d1cdbfa2c4b7f0f52f0ffe
error pushing image: failed to push to destination index.docker.io/******/**-qs-python:0.0.3: MANIFEST_BLOB_UNKNOWN: blob unknown to registry; sha256:2d21c767035c4593de8bf7ad9781aa83ba110871d1a50871192f4e3480e6f11d
[31m
Pipeline failed on stage 'from-build-pack' : container 'step-build-container-build'. The execution of the pipeline has stopped.[0m
